Workbook

Sheet 🏥 맞춤 시뮬레이터
B1: ✅ USP COMPANY | 도입 병원 47개 | 누적 절세 138억 | 추징 0건 (2019~2026) | 본 시뮬레이터 수치는 실제 운영 데이터 기반입니다
B2: 페이닥터 급여구조 최적화 시뮬레이터 | USP COMPANY
B3: ✏️ 노란색 셀 5개만 입력하세요 → 우리 병원 절감액이 바로 계산됩니다
B5: 📋 우리 병원 정보 입력 | F5: 💰 절감 효과 자동 계산
B6: 병원 유형 | C6: 개인사업자 | F6: ① 네트→그로스 전환 세금 절감 (인건비 감소 ✕ — 비용처리 증가 → 세금 감소 ✓) | G6: =ROUND((AA9*VLOOKUP(AA9,_기준표!$A$2:$C$7,2,TRUE())-AA9*VLOOKUP(AA9,_기준표!$A$2:$C$7,3,TRUE()))*12*AA8/10000,0) -> 4482 | H6: 만원/년 | AA6: =C6 -> 개인사업자
B7: 연 순수익 | C7: 30000 | D7: 만원 | F7: ② 법인세 추가 절감 | G7: =ROUND((AA9*VLOOKUP(AA9,_기준표!$A$2:$C$7,2,TRUE())-AA9*VLOOKUP(AA9,_기준표!$A$2:$C$7,3,TRUE()))*AA11*12*AA8/10000,0) -> 1873 | H7: 만원/년 | AA7: =C7*10000 -> 300000000
B8: 페이닥터 인원 | C8: 3 | D8: 명 | F8: ③ 복지기금 절세 | G8: =ROUND(AA10*AA12/10000,0) -> 1500 | H8: 만원/년 | AA8: =C8 -> 3
B9: 월 평균 실수령 | C9: 1500 | D9: 만원 | F9: ④ 페이닥터 절세 (개인) | G9: ='💰 페이닥터 절세전략'!D20 -> 712 | H9: 만원/년 | AA9: =C9*10000 -> 15000000
B10: 복지기금 출연 | C10: 5000 | D10: 만원/년 | F10: ※ ④는 페이닥터 개인 절세 (총합 미포함) | AA10: =C10*10000 -> 50000000
AA11: =IF(AA6="개인사업자",VLOOKUP(AA7,_기준표!$E$2:$F$8,2,TRUE()),VLOOKUP(AA7*0.9,_기준표!$H$2:$I$4,2,TRUE())) -> 0.418
B12: =" 📐 산출 근거: ① 전환절감 "&TEXT(G6,"#,##0")&"만원"&" + ② 법인세 "&TEXT(G7,"#,##0")&"만원"&" + ③ 복지기금 "&TEXT(G8,"#,##0")&"만원"&" = 병원 총 절감 "&TEXT(G6+G7+G8,"#,##0")&"만원/년" -> 📐 산출 근거: ① 전환절감 4,482만원 + ② 법인세 1,873만원 + ③ 복지기금 1,500만원 = 병원 총 절감 7,855만원/년 | AA12: 0.3
B14: 🏆 병원 연간 총 절감액 | F14: =G6+G7+G8 -> 7855 | H14: 만원/년
B15: 📈 10년 누적 예상 절감액 | F15: =(G6+G7+G8)*10 -> 78550 | H15: 만원
B17: 📅 우리 병원 기준 — 연도별 누적 절감 예상
B18: 항목 | C18: 1년차 | D18: 2년차 | E18: 3년차 | G18: 3년 누적 | H18: 10년 누적
B19: ① 네트→그로스 전환 세금 절감 | C19: =G6 -> 4482 | D19: =G6*2 -> 8964 | E19: =G6*3 -> 13446 | G19: =G6*3 -> 13446 | H19: =G6*10 -> 44820
B20: ② 법인세 추가 절감 | C20: =G7 -> 1873 | D20: =G7*2 -> 3746 | E20: =G7*3 -> 5619 | G20: =G7*3 -> 5619 | H20: =G7*10 -> 18730
B21: ③ 복지기금 절세 | C21: =G8 -> 1500 | D21: =G8*2 -> 3000 | E21: =G8*3 -> 4500 | G21: =G8*3 -> 4500 | H21: =G8*10 -> 15000
B22: 병원 누적 총 절감 | C22: =G6+G7+G8 -> 7855 | D22: =(G6+G7+G8)*2 -> 15710 | E22: =(G6+G7+G8)*3 -> 23565 | G22: =(G6+G7+G8)*3 -> 23565 | H22: =(G6+G7+G8)*10 -> 78550
B23: ※ 위 수치는 현재 입력값 기준 추정입니다. 실제 절감액은 USP 전문가 진단을 통해 정확히 산출합니다.
B25: 💡 복지기금 출연 실익 — 왜 손해가 아닌가?
B26: 항목 | G26: 금액 | H26: 설명
B27: 출연 계획액 | G27: =C10 -> 5000 | H27: 만원/년 / 입력값
B28: 병원 절세액 | G28: =ROUND(AA10*AA12/10000,0) -> 1500 | H28: 만원/년 / 출연액 × 30% (보수적)
B29: 출연 실비용 | G29: =ROUND(C10-G28,0) -> 3500 | H29: 만원/년 / 실제 병원 부담
B30: 직원 복지액 | G30: =ROUND(C10*0.8,0) -> 4000 | H30: 만원/년 / 직원 세금 0원
B31: =" ✅ "&TEXT(C10,"#,##0")&"만원 출연 → 절세 "&TEXT(G28,"#,##0")&"만 + 직원복지 "&TEXT(ROUND(C10*0.8,0),"#,##0")&"만 = 실질 총편익 "&TEXT(G28+ROUND(C10*0.8,0),"#,##0")&"만원" -> ✅ 5,000만원 출연 → 절세 1,500만 + 직원복지 4,000만 = 실질 총편익 5,500만원
B32: ※ 절세율은 보수적 30% 기준 추정값입니다. 정확한 수치는 USP 무료 상담에서 산출해드립니다.
B34: 🔍 계산 검증용 — 숫자가 어떻게 나왔는지 궁금할 때만 확인하세요
B35: 항목 | C35: 1인/월 | D35: 1인/년 | F35: 전체/년 | H35: 비고
B36: NET 기준 병원 실부담 (현재) | C36: =ROUND((AA9*VLOOKUP(AA9,_기준표!$A$2:$C$7,2,TRUE()))/10000,0) -> 2375 | D36: =ROUND((AA9*VLOOKUP(AA9,_기준표!$A$2:$C$7,2,TRUE()))*12/10000,0) -> 28494 | F36: =ROUND((AA9*VLOOKUP(AA9,_기준표!$A$2:$C$7,2,TRUE()))*12*AA8/10000,0) -> 85482 | H36: NET 기준 실부담 (현재)
B37: GROSS 전환 후 병원 부담 | C37: =ROUND((AA9*VLOOKUP(AA9,_기준표!$A$2:$C$7,3,TRUE()))/10000,0) -> 2250 | D37: =ROUND((AA9*VLOOKUP(AA9,_기준표!$A$2:$C$7,3,TRUE()))*12/10000,0) -> 27000 | F37: =ROUND((AA9*VLOOKUP(AA9,_기준표!$A$2:$C$7,3,TRUE()))*12*AA8/10000,0) -> 81000 | H37: 세전 급여만 부담
B38: ✅ 절감액 (①번 항목) | C38: =ROUND((AA9*VLOOKUP(AA9,_기준표!$A$2:$C$7,2,TRUE())-AA9*VLOOKUP(AA9,_기준표!$A$2:$C$7,3,TRUE()))/10000,0) -> 125 | D38: =ROUND((AA9*VLOOKUP(AA9,_기준표!$A$2:$C$7,2,TRUE())-AA9*VLOOKUP(AA9,_기준표!$A$2:$C$7,3,TRUE()))*12/10000,0) -> 1494 | F38: =ROUND((AA9*VLOOKUP(AA9,_기준표!$A$2:$C$7,2,TRUE())-AA9*VLOOKUP(AA9,_기준표!$A$2:$C$7,3,TRUE()))*12*AA8/10000,0) -> 4482 | H38: 네트→그로스 전환 세금 절감
B39: ✅ 법인세 절감 (②번 항목) | C39: =ROUND((AA9*VLOOKUP(AA9,_기준표!$A$2:$C$7,2,TRUE())-AA9*VLOOKUP(AA9,_기준표!$A$2:$C$7,3,TRUE()))*AA11/10000,0) -> 52 | D39: =ROUND((AA9*VLOOKUP(AA9,_기준표!$A$2:$C$7,2,TRUE())-AA9*VLOOKUP(AA9,_기준표!$A$2:$C$7,3,TRUE()))*AA11*12/10000,0) -> 624 | F39: =ROUND((AA9*VLOOKUP(AA9,_기준표!$A$2:$C$7,2,TRUE())-AA9*VLOOKUP(AA9,_기준표!$A$2:$C$7,3,TRUE()))*AA11*12*AA8/10000,0) -> 1873 | H39: 절감액 × 세율
B40: ※ 적용 세율: 병원 유형(개인사업자/법인) × 연 순수익 기준 자동 적용 | 만원 단위 표시
B43: 🏢 법인 vs 개인사업자 — 병원 유형별 절세 효과 비교
B44: 위 시뮬레이터에서 병원 유형을 '법인'으로 변경하면 법인세율이 자동 적용됩니다. 아래는 유형별 세율 차이와 전환 효과 요약입니다.
B45: 구분 | C45: 개인사업자 | F45: 법인 | H45: 비고
B46: 세율 구간 | C46: 소득세 6.6%~49.5% (지방세 포함) | F46: 법인세 9%~21% (지방세 포함) | H46: 법인이 고소득일수록 유리
B47: 순수익 3억 적용 세율 | C47: 약 41.8% | F47: 약 19.8% | H47: 법인 전환 시 세율 약 22%p 감소
...

Sheet 📋 DC형·복지기금 상세
B2: DC형 퇴직연금 + 사내근로복지기금 — 상세 설계 가이드
B3: 아래 수치는 메인 시트 입력값과 자동 연동됩니다.
B5: 메인 시뮬레이터 연동 현황
B6: 병원 유형 | C6: ='🏥 맞춤 시뮬레이터'!C6 -> 개인사업자
B7: 연 순수익 | C7: =TEXT('🏥 맞춤 시뮬레이터'!C7,"#,##0")&"만원 ("&TEXT(INT('🏥 맞춤 시뮬레이터'!C7/10000),"#,##0")&"억원)" -> 30,000만원 (3억원)
B8: 페이닥터 | C8: ='🏥 맞춤 시뮬레이터'!C8&"명" -> 3명
B9: 월 실수령 | C9: =TEXT('🏥 맞춤 시뮬레이터'!C9,"#,##0")&"만원" -> 1,500만원
B10: 복지기금 | C10: =TEXT('🏥 맞춤 시뮬레이터'!C10,"#,##0")&"만원/년" -> 5,000만원/년
B12: ① DC형 퇴직연금 — 퇴직금 분쟁 원천 차단
B13: 구분 | C13: DB형 (현재) | D13: DC형 (전환 후) | E13: 핵심 효과
B14: 분쟁 리스크 | C14: NET 기준 청구 가능 → 소송 리스크 상존 | D14: 세전 기준 명시 → 분쟁 소지 0 | E14: 노무 리스크 완전 제거
B15: 퇴직금 기준 | C15: 실수령액 기준 분쟁 (법적으로 다툼 가능) | D15: 계약서에 세전 기준 명시 (다툼 자체 불가) | E15: 계약서 일원화
B16: 세금 처리 | C16: 지급 시 비용 처리 | D16: 매년 전액 비용 처리 | E16: 법인세 절감 (§19)
B17: 비용 예측 | C17: 퇴직금 규모 불투명 | D17: 연봉 1/12 적립 → 확정 | E17: 재무 예측 가능
B18: 직원 혜택 | C18: 퇴직 시 일시금만 | D18: 연금 또는 일시금 선택 | E18: 직원 만족도 향상
B21: ② 복지기금 출연액 구간별 시뮬레이션 (세율 30% 보수적 기준)
B22: 출연액(만원) | C22: 병원 절세(만원) | D22: 출연 실비용(만원) | E22: 직원복지(만원) | F22: 실질 총편익(만원)
B23: 3000 | C23: 900 | D23: 2100 | E23: 2400 | F23: 3300
B24: 5000 | C24: 1500 | D24: 3500 | E24: 4000 | F24: 5500
B25: 10000 | C25: 3000 | D25: 7000 | E25: 8000 | F25: 11000
B26: 20000 | C26: 6000 | D26: 14000 | E26: 16000 | F26: 22000
B27: 30000 | C27: 9000 | D27: 21000 | E27: 24000 | F27: 33000
B28: 50000 | C28: 15000 | D28: 35000 | E28: 40000 | F28: 55000
B30: ※ 절세율 30% 보수적 기준 추정값 | 실제 절세율은 병원 세율 구조에 따라 달라집니다 — 정확한 수치는 무료 상담에서
B32: 📞 USP Company | 1533-6441 | pf.kakao.com/_SxdxfxcG

Sheet 💰 페이닥터 절세전략
B2: 페이닥터 개인 절세 전략 — 그로스 전환 후 바로 활용 가능
B3: 그로스 전환 후 페이닥터 선생님이 직접 챙길 수 있는 절세 전략입니다. 병원이 안내해드리면 전환 설득에도 효과적입니다.
B5: ① 비과세 복지수당 — 월 최대 80만원 추가 실수령 (세금 0원)
B6: 항목 | C6: 월 한도 | D6: 연간 효과 | E6: 비고 | F6: 법적 근거
B7: 식대 | C7: 20만원 | D7: 연 240만원 | E7: 비과세 한도 내 | F7: 소득세법 §12
B8: 자가운전보조금 | C8: 20만원 | D8: 연 240만원 | E8: 본인 차량 사용 | F8: 소득세법 §12
B9: 연구개발비 | C9: 20만원 | D9: 연 240만원 | E9: 의사 연구활동 | F9: 소득세법 §12
B10: 출산·육아지원금 | C10: 20만원 | D10: 연 240만원 | E10: 해당자 적용 | F10: 소득세법 §12
B11: 합계 | C11: 월 80만원 | D11: 연 960만원 | E11: 4개 항목 동시
B14: ② 절세 전략별 연간 효과 (시나리오별)
B15: 전략 | C15: 보수적 (만원/년) | D15: 평균 (만원/년) | E15: 최대 (만원/년) | F15: 비고
B16: 연금저축 + IRP 세액공제 | C16: 148 | D16: 184 | E16: 270 | F16: 연 900만 한도
B17: 벤처투자 소득공제 | C17: - | D17: 300 | E17: 1155 | F17: 해당자만 / 조특법 §16
B18: 맞벌이 세금 최적화 | C18: 0 | D18: 100 | E18: 200 | F18: 배우자 소득 있을 때
B19: 기부금·보험료·교육비 | C19: 67 | D19: 128 | E19: 190 | F19: 공제 항목 챙기기
B20: 합계 | C20: =SUM(C16:C19) -> 215 | D20: =SUM(D16:D19) -> 712 | E20: =SUM(E16:E19) -> 1815
B22: ※ 벤처투자 소득공제는 조특법 §16 요건 충족 필요. 개인별 상황에 따라 실제 효과가 다릅니다.
B24: 📞 페이닥터 절세전략 상담 | 1533-6441 | pf.kakao.com/_SxdxfxcG

Sheet 💬 페이닥터 설득 스크립트
B2: 페이닥터 선생님 설득 스크립트 — 원장님이 직접 쓰실 수 있도록
B3: '그로스로 바꾸면 내가 손해 아닌가요?' — 이 질문에 막히지 않도록 상황별 대응을 준비했습니다.
B5: STEP 1 | 첫 대화 — 거부감 없이 꺼내는 방법
B6: 상황 | C6: 선생님이 아무 반응 없을 때 — 처음 꺼낼 때
B7: 추천 멘트 | C7: "선생님, 저도 지금 급여 구조 공부하고 있는데요. 지금 네트 계약이 선생님한테도 사실 좋은 건지 한번 같이 확인해보고 싶어서요. 10분만 시간 되실까요?"
B8: 핵심 포인트 | C8: '병원이 바꾸고 싶다'가 아니라 '선생님한테도 좋은지 확인하자'는 프레임으로 시작 → 선생님이 방어적으로 반응하지 않음
B10: STEP 2 | 반발 시나리오별 대응 — 가장 많이 나오는 질문 5가지
B11: ❓ "그로스로 바꾸면 저 손해 아닌가요?"
B12: 💬 추천 답변 | C12: 지금 네트 1,500만원이면 그로스로 바꿔도 실수령은 동일하게 맞춰드립니다. 차이는 선생님이 직접 세금 신고하게 되는 것뿐이에요. 그런데 그게 오히려 유리해요. 연금저축·IRP로 연간 184만원 절세가 생기거든요. 지금 네트에서는 이 혜택을 못 받으세요.
B13: 🔑 핵심 논리 | C13: 실수령 동일 + 개인 절세 184만원 추가
B15: ❓ "세금 신고 번거롭지 않아요?"
B16: 💬 추천 답변 | C16: 5월 종합소득세 신고 한 번이에요. 세무사 비용 20~30만원 정도면 다 처리해드려요. 연 184만원 절세에서 30만원 빼도 150만원 이득이에요.
B17: 🔑 핵심 논리 | C17: 번거로움 < 이득
B19: ❓ "퇴직금은요? 그로스 기준이면 더 적어지지 않나요?"
B20: 💬 추천 답변 | C20: 지금 네트 계약이면 퇴직금 기준이 오히려 불명확해요. '내가 받은 1,500만원 기준으로 달라'고 하면 법적으로 다툼이 생겨요. 그로스로 바꾸면 세전 계약서에 명시되니까 기준이 명확해지고 DC형 연금으로 매년 적립되니 선생님한테 더 안전합니다.
B21: 🔑 핵심 논리 | C21: 그로스 = 퇴직금 기준 명확 + DC형 연금 적립
B23: ❓ "다른 병원 원장들도 이렇게 해요?"
B24: 💬 추천 답변 | C24: USP에서 도입한 병원만 47개고 2019년부터 추징 0건이에요. 강남 피부과 원장님도 처음에 세무조사 걱정하셨는데 3년간 4억 7,900만원 절세하셨어요. 제가 자료 보여드릴게요.
B25: 🔑 핵심 논리 | C25: 47개 병원 / 추징 0건 / 실제 사례 제시
B27: ❓ "갑자기 바꾸면 관계가 불편해지지 않을까요?"
B28: 💬 추천 답변 | C28: 선생님 실수령은 그대로예요. 병원 부담은 오히려 줄어들어요. 바꾸기 전에 선생님한테 먼저 이 자료(페이닥터 절세전략) 보여드리면 '나한테도 좋네요'가 되거든요. 관계가 불편해지는 게 아니라 오히려 더 신뢰가 생기는 경우가 많아요.
B29: 🔑 핵심 논리 | C29: 실수령 유지 + 페이닥터 절세 자료 먼저 공유
B32: STEP 3 | 마무리 — 선생님 동의 이끌어내기
B33: 추천 클로징 | C33: "선생님, 실수령은 지금과 똑같이 맞춰드리고요. 오히려 연금저축으로 연간 150만원 이상 절세도 생기세요. 저도 전문가랑 한번 더 확인하고 진행할 건데, 같이 검토해보시겠어요?"
B35: 📞 USP Company | 전화 1533-6441 | pf.kakao.com/_SxdxfxcG

Sheet 📊 참고사례
B2: 실전 사례 — 강남 A 피부과·성형외과 (원장님 요청으로 익명 처리)
B4: 병원 프로필
B5: 진료과목 | C5: 피부과·성형외과 (강남 소재)
B6: 연 매출 | C6: 38억원 (순수익 8억원)
B7: 페이닥터 | C7: 4명 (전원 NET → GROSS 전환 완료)
B8: 구조 도입 | C8: 2023년 3월
B11: 3년 운영 성과
B12: 항목 | C12: 도입 전 (2022) | D12: 1년차 (2023) | E12: 2년차 (2024) | F12: 3년차 (2025)
B13: 연간 세금 | C13: 3억 4,800만 | D13: 2억 1,500만 | E13: 1억 8,200만 | F13: 1억 6,800만
B14: 연간 절세액 | C14: — | D14: 1억 3,300만 | E14: 1억 6,600만 | F14: 1억 8,000만
B15: 누적 절세액 | C15: — | D15: 1억 3,300만 | E15: 2억 9,900만 | F15: 4억 7,900만
B16: 페이닥터 비용(4명) | C16: 1억 1,400만/년 | D16: 9,600만/년 | E16: 9,600만/년 | F16: 9,600만/년
B17: GROSS 전환 누적절감 | C17: — | D17: 1,800만 | E17: 3,600만 | F17: 5,400만
B18: 세무조사 | C18: 통보 1건 | D18: 0건 | E18: 0건 | F18: 0건
B21: 💡 내가 입력한 값 기준 — 우리 병원 예상 효과 (메인 시트 자동 연동)
B22: ='🏥 맞춤 시뮬레이터'!C6&" / 순수익 "&TEXT('🏥 맞춤 시뮬레이터'!C7,"#,##0")&"만원 / 페이닥터 "&'🏥 맞춤 시뮬레이터'!C8&"명 기준" -> 개인사업자 / 순수익 30,000만원 / 페이닥터 3명 기준
B23: 항목 | C23: 연간 절감 | D23: 3년 누적 | E23: 10년 누적 | F23: 단위
B24: ① 네트→그로스 전환 세금 절감 | C24: ='🏥 맞춤 시뮬레이터'!G6 -> 4482 | D24: ='🏥 맞춤 시뮬레이터'!G6*3 -> 13446 | E24: ='🏥 맞춤 시뮬레이터'!G6*10 -> 44820 | F24: 만원
B25: ② 법인세 추가 절감 | C25: ='🏥 맞춤 시뮬레이터'!G7 -> 1873 | D25: ='🏥 맞춤 시뮬레이터'!G7*3 -> 5619 | E25: ='🏥 맞춤 시뮬레이터'!G7*10 -> 18730 | F25: 만원
B26: ③ 복지기금 절세 | C26: ='🏥 맞춤 시뮬레이터'!G8 -> 1500 | D26: ='🏥 맞춤 시뮬레이터'!G8*3 -> 4500 | E26: ='🏥 맞춤 시뮬레이터'!G8*10 -> 15000 | F26: 만원
B27: 병원 총 절감 | C27: ='🏥 맞춤 시뮬레이터'!F14 -> 7855 | D27: ='🏥 맞춤 시뮬레이터'!F14*3 -> 23565 | E27: ='🏥 맞춤 시뮬레이터'!F14*10 -> 78550 | F27: 만원
B28: ※ 메인 시트 입력값을 변경하면 위 수치가 자동 업데이트됩니다.
B30: 원장님 후기
B31: "처음에는 세무조사가 무서워서 3년을 망설였습니다. 그런데 실제로 구조를 만들고 나니, 세무 리스크가 완전히 사라졌습니다. 퇴직금 분쟁 걱정도 없어졌고, 3년간 아낀 4억 7,900만원을 보면 진작 할 걸 싶습니다." — 강남 A피부과 원장님 (익명)
B34: 📞 USP Company | 전화: 1533-6441 | 카카오톡: pf.kakao.com/_SxdxfxcG/chat
B37: 추가 사례 — 규모별 참고
B38: 사례 B | 경기도 B 내과 (원장님 요청으로 익명)
B39: 진료과목 | C39: 내과 (경기도 소재)
B40: 연 매출 | C40: 18억원 (순수익 3억 5,000만원)
B41: 페이닥터 | C41: 2명 (NET → GROSS 전환 완료)
B42: 구조 도입 | C42: 2022년 7월
B43: 2년 운영 성과
B44: 항목 | C44: 도입 전 | D44: 1년차 | E44: 2년차 | F44: 누적
B45: 연간 세금 | C45: 6,800만 | D45: 4,200만 | E45: 3,800만 | F45: —
B46: 연간 절세액 | C46: — | D46: 2,600만 | E46: 3,000만 | F46: 5,600만
B47: 누적 절세액 | C47: — | D47: 2,600만 | E47: 5,600만 | F47: 5,600만
B48: 세무조사 | C48: 0건 | D48: 0건 | E48: 0건 | F48: 0건
B51: 사례 C | 서울 C 피부과 (원장님 요청으로 익명)
B52: 진료과목 | C52: 피부과 (서울 소재)
B53: 연 매출 | C53: 12억원 (순수익 2억원)
...

Sheet 📝 무료 진단 신청서
B2: 📝 USP Company 급여구조 무료 진단 신청서
B3: 아래 내용을 작성하신 후 카카오톡으로 보내주세요 → pf.kakao.com/_SxdxfxcG/chat
B4: 작성 즉시 담당 전문가가 연락드립니다. 전화 영업 없이 카카오톡으로만 연락드립니다.
B6: 병원 기본 정보
B7: 병원명 (또는 닉네임) | C7: 예) ○○내과, 강남병원 등 (익명 가능)
B8: 진료과목 | C8: 예) 피부과, 성형외과, 내과 등
B9: 병원 유형 | C9: 개인사업자 / 법인 (해당 항목에 ○ 표시)
B10: 연 순수익 (대략) | C10: 예) 약 3억원, 5억원 등 (정확하지 않아도 됩니다)
B11: 페이닥터 인원 | C11: 예) 2명, 3명 등
B12: 현재 계약 방식 | C12: NET 계약 / GROSS 계약 / 혼합 (해당 항목에 ○ 표시)
B13: 월 평균 실수령 (대략) | C13: 예) 약 1,200만원, 1,500만원 등
B16: 고민 사항 (해당 항목에 ✓ 표시)
B17: □ 세금이 너무 많이 나와서 줄이고 싶다
B18: □ 페이닥터 퇴직금 분쟁이 걱정된다
B19: □ 네트 계약의 세금 처리가 복잡하고 불안하다
B20: □ 페이닥터를 그로스로 전환하고 싶은데 방법을 모른다
B21: □ 복지기금이나 DC형 퇴직연금에 관심이 있다
B22: □ 기타: _________________________________
B25: 추가 메모 (선택)
B26: 자유롭게 작성해주세요. (현재 상황, 궁금한 점, 원하는 결과 등)
B28: 📤 이 파일을 저장 후 카카오톡으로 전송해주세요
B29: 💬 카카오톡: pf.kakao.com/_SxdxfxcG/chat
B30: 📞 전화 상담 선호 시: 1533-6441
B32: ※ 수집된 정보는 급여구조 진단 목적으로만 사용되며 외부에 제공되지 않습니다.

Sheet _기준표
A2: 10000000 | B2: 1.58 | C2: 1.5 | E2: 12000000 | F2: 0.066 | H2: 200000000 | I2: 0.09
A3: 15000000 | B3: 1.583 | C3: 1.5 | E3: 46000000 | F3: 0.165 | H3: 20000000000 | I3: 0.19
A4: 20000000 | B4: 1.585 | C4: 1.5 | E4: 88000000 | F4: 0.264 | H4: 999999999999 | I4: 0.21
A5: 25000000 | B5: 1.584 | C5: 1.5 | E5: 150000000 | F5: 0.385
A6: 30000000 | B6: 1.583 | C6: 1.5 | E6: 300000000 | F6: 0.418
A7: 35000000 | B7: 1.586 | C7: 1.5 | E7: 500000000 | F7: 0.44
E8: 999999999999 | F8: 0.495
